Failure # 1 (occurred at 2022-07-12_17-49-42)
[36mray::ImplicitFunc.train()[39m (pid=2163402, ip=131.227.165.153, repr=_objective)
  File "/home/diptesh/anaconda3/envs/aggDet/lib/python3.8/site-packages/ray/tune/trainable.py", line 360, in train
    result = self.step()
  File "/home/diptesh/anaconda3/envs/aggDet/lib/python3.8/site-packages/ray/tune/function_runner.py", line 404, in step
    self._report_thread_runner_error(block=True)
  File "/home/diptesh/anaconda3/envs/aggDet/lib/python3.8/site-packages/ray/tune/function_runner.py", line 574, in _report_thread_runner_error
    raise e
  File "/home/diptesh/anaconda3/envs/aggDet/lib/python3.8/site-packages/ray/tune/function_runner.py", line 277, in run
    self._entrypoint()
  File "/home/diptesh/anaconda3/envs/aggDet/lib/python3.8/site-packages/ray/tune/function_runner.py", line 349, in entrypoint
    return self._trainable_func(
  File "/home/diptesh/anaconda3/envs/aggDet/lib/python3.8/site-packages/ray/tune/function_runner.py", line 645, in _trainable_func
    output = fn()
  File "/home/diptesh/anaconda3/envs/aggDet/lib/python3.8/site-packages/transformers/integrations.py", line 288, in dynamic_modules_import_trainable
    return trainable(*args, **kwargs)
  File "/home/diptesh/anaconda3/envs/aggDet/lib/python3.8/site-packages/ray/tune/utils/trainable.py", line 410, in inner
    trainable(config, **fn_kwargs)
  File "/home/diptesh/anaconda3/envs/aggDet/lib/python3.8/site-packages/transformers/integrations.py", line 189, in _objective
    local_trainer.train(resume_from_checkpoint=checkpoint, trial=trial)
  File "/home/diptesh/anaconda3/envs/aggDet/lib/python3.8/site-packages/transformers/trainer.py", line 1409, in train
    return inner_training_loop(
  File "/home/diptesh/anaconda3/envs/aggDet/lib/python3.8/site-packages/transformers/trainer.py", line 1651, in _inner_training_loop
    tr_loss_step = self.training_step(model, inputs)
  File "/home/diptesh/anaconda3/envs/aggDet/lib/python3.8/site-packages/transformers/trainer.py", line 2345, in training_step
    loss = self.compute_loss(model, inputs)
  File "/tmp/ipykernel_2157418/3804557109.py", line 6, in compute_loss
AttributeError: 'dict' object has no attribute 'to'
